<?xml version="1.0" ?>
<!-- =================================================================================== -->
<!-- |    This document was autogenerated by xacro from lawd.xacro                     | -->
<!-- |    EDITING THIS FILE BY HAND IS NOT RECOMMENDED                                 | -->
<!-- =================================================================================== -->
<robot name="lawd">
  <material name="silver">
    <color rgba="0.700 0.700 0.700 1.000"/>
  </material>
  <material name="yellow">
    <color rgba="1 1 0 1.000"/>
  </material>
  <material name="red">
    <color rgba="1 0 0 1.000"/>
  </material>
  <material name="brown">
    <color rgba="0.54 0.27 0.074 1.000"/>
  </material>
  <material name="white">
    <color rgba="1 1 1 1.000"/>
  </material>
  <material name="black">
    <color rgba="0 0 0 1.000"/>
  </material>
  <material name="violet">
    <color rgba="0.933 0.510 0.933 1.000"/>
  </material>
  <material name="green">
    <color rgba="0 1 0 1.000"/>
  </material>
  <material name="blue">
    <color rgba="0 0 1 1.000"/>
  </material>


  <ros2_control name="GazeboSystem" type="system">
    <hardware>
      <plugin>gazebo_ros2_control/GazeboSystem</plugin>
    </hardware>
    <joint name="ext_frontleftfirst">
      <command_interface name="position">
    </command_interface>
      <state_interface name="velocity"/>
      <state_interface name="position"/>
    </joint>
    <joint name="ext_backleftfirst">
      <command_interface name="position">
    </command_interface>
      <state_interface name="velocity"/>
      <state_interface name="position"/>
    </joint>
    <joint name="ext_frontrightfirst">
      <command_interface name="position">
    </command_interface>
      <state_interface name="velocity"/>
      <state_interface name="position"/>
    </joint>
    <joint name="ext_backrightfirst">
      <command_interface name="position">
    </command_interface>
      <state_interface name="velocity"/>
      <state_interface name="position"/>
    </joint>
    <joint name="first_frontleftsec">
      <command_interface name="position">
    </command_interface>
      <state_interface name="velocity"/>
      <state_interface name="position"/>
    </joint>
    <joint name="first_backleftsec">
      <command_interface name="position">
    </command_interface>
      <state_interface name="velocity"/>
      <state_interface name="position"/>
    </joint>
    <joint name="first_frontrightsec">
      <command_interface name="position">
    </command_interface>
      <state_interface name="velocity"/>
      <state_interface name="position"/>
    </joint>
    <joint name="first_backrightsec">
      <command_interface name="position">
    </command_interface>
      <state_interface name="velocity"/>
      <state_interface name="position"/>
    </joint>
    <joint name="base_frontleftwing">
      <command_interface name="position">
    </command_interface>
      <state_interface name="velocity"/>
      <state_interface name="position"/>
    </joint>
    <joint name="base_backleftwing">
      <command_interface name="position">
    </command_interface>
      <state_interface name="velocity"/>
      <state_interface name="position"/>
    </joint>
    <joint name="base_frontrightwing">
      <command_interface name="position">
    </command_interface>
      <state_interface name="velocity"/>
      <state_interface name="position"/>
    </joint>
    <joint name="base_backrightwing">
      <command_interface name="position">
    </command_interface>
      <state_interface name="velocity"/>
      <state_interface name="position"/>
    </joint>
    <joint name="wing_frontleftprop">
      <command_interface name="velocity">
    </command_interface>
      <state_interface name="velocity"/>
      <state_interface name="position"/>
    </joint>
    <joint name="wing_backleftprop">
      <command_interface name="velocity">
    </command_interface>
      <state_interface name="velocity"/>
      <state_interface name="position"/>
    </joint>
    <joint name="wing_frontrightprop">
      <command_interface name="velocity">
    </command_interface>
      <state_interface name="velocity"/>
      <state_interface name="position"/>
    </joint>
    <joint name="wing_backrightprop">
      <command_interface name="velocity">
    </command_interface>
      <state_interface name="velocity"/>
      <state_interface name="position"/>
    </joint>
  </ros2_control>
  <gazebo reference="base_link">
    <material>Gazebo/White</material>
    <mu1>0.2</mu1>
    <mu2>0.2</mu2>
    <self_collide>true</self_collide>
    <gravity>true</gravity>
  </gazebo>
  <gazebo reference="front_left_ext">
    <material>Gazebo/Blue</material>
    <mu1>0.2</mu1>
    <mu2>0.2</mu2>
    <self_collide>true</self_collide>
  </gazebo>
  <gazebo reference="back_left_ext">
    <material>Gazebo/Blue</material>
    <mu1>0.2</mu1>
    <mu2>0.2</mu2>
    <self_collide>true</self_collide>
  </gazebo>
  <gazebo reference="front_right_ext">
    <material>Gazebo/Blue</material>
    <mu1>0.2</mu1>
    <mu2>0.2</mu2>
    <self_collide>true</self_collide>
  </gazebo>
  <gazebo reference="back_right_ext">
    <material>Gazebo/Blue</material>
    <mu1>0.2</mu1>
    <mu2>0.2</mu2>
    <self_collide>true</self_collide>
  </gazebo>
  <gazebo reference="front_left_first">
    <material>Gazebo/Red</material>
    <mu1>0.2</mu1>
    <mu2>0.2</mu2>
    <self_collide>true</self_collide>
  </gazebo>
  <gazebo reference="back_left_first">
    <material>Gazebo/Red</material>
    <mu1>0.2</mu1>
    <mu2>0.2</mu2>
    <self_collide>true</self_collide>
  </gazebo>
  <gazebo reference="back_right_first">
    <material>Gazebo/Red</material>
    <mu1>0.2</mu1>
    <mu2>0.2</mu2>
    <self_collide>true</self_collide>
  </gazebo>
  <gazebo reference="front_right_first">
    <material>Gazebo/Red</material>
    <mu1>0.2</mu1>
    <mu2>0.2</mu2>
    <self_collide>true</self_collide>
  </gazebo>
  <gazebo reference="front_left_sec">
    <material>Gazebo/Brown</material>
    <mu1>0</mu1>
    <mu2>0</mu2>
    <self_collide>true</self_collide>
  </gazebo>
  <gazebo reference="back_left_sec">
    <material>Gazebo/Brown</material>
    <mu1>0</mu1>
    <mu2>0</mu2>
    <self_collide>true</self_collide>
  </gazebo>
  <gazebo reference="front_right_sec">
    <material>Gazebo/Brown</material>
    <mu1>0</mu1>
    <mu2>0</mu2>
    <self_collide>true</self_collide>
  </gazebo>
  <gazebo reference="back_right_sec">
    <material>Gazebo/Brown</material>
    <mu1>0</mu1>
    <mu2>0</mu2>
    <self_collide>true</self_collide>
  </gazebo>
  <gazebo reference="front_left_wing">
    <material>Gazebo/Yellow</material>
    <mu1>0.2</mu1>
    <mu2>0.2</mu2>
    <self_collide>true</self_collide>
  </gazebo>
  <gazebo reference="front_right_wing">
    <material>Gazebo/Yellow</material>
    <mu1>0.2</mu1>
    <mu2>0.2</mu2>
    <self_collide>true</self_collide>
  </gazebo>
  <gazebo reference="back_left_wing">
    <material>Gazebo/Green</material>
    <mu1>0.2</mu1>
    <mu2>0.2</mu2>
    <self_collide>true</self_collide>
  </gazebo>
  <gazebo reference="back_right_wing">
    <material>Gazebo/Green</material>
    <mu1>0.2</mu1>
    <mu2>0.2</mu2>
    <self_collide>true</self_collide>
  </gazebo>
  <gazebo reference="back_left_prop">
    <material>Gazebo/Black</material>
    <mu1>0.2</mu1>
    <mu2>0.2</mu2>
    <self_collide>true</self_collide>
  </gazebo>
  <gazebo reference="back_right_prop">
    <material>Gazebo/Violet</material>
    <mu1>0.2</mu1>
    <mu2>0.2</mu2>
    <self_collide>true</self_collide>
  </gazebo>
  <gazebo reference="front_right_prop">
    <material>Gazebo/Black</material>
    <mu1>0.2</mu1>
    <mu2>0.2</mu2>
    <self_collide>true</self_collide>
  </gazebo>
  <gazebo reference="front_left_prop">
    <material>Gazebo/Violet</material>
    <mu1>0.2</mu1>
    <mu2>0.2</mu2>
    <self_collide>true</self_collide>
  </gazebo>
  <gazebo>
    <plugin filename="libgazebo_ros2_control.so" name="gazebo_ros">
      <parameters>/home/vedh/workspaces/lawd_ws/install/lawd_description/share/lawd_description/config/my_controllers.yaml</parameters>
      <parameters>/home/vedh/workspaces/lawd_ws/install/lawd_description/share/lawd_description/config/gaz_ros2_ctl_use_sim.yaml</parameters>
    </plugin>
  </gazebo>


  <link name="base_link">
    <inertial>
      <origin rpy="0 0 0" xyz="2.480529914137719e-05 -9.790818202397133e-05 0.23900096831654172"/>
      <mass value="0.996540823201331"/>
      <inertia ixx="0.006012" ixy="1e-06" ixz="-6e-06" iyy="0.00603" iyz="0.0" izz="0.010866"/>
    </inertial>
    <visual>
      <origin rpy="0 0 0" xyz="0 0 0"/>
      <geometry>
        <mesh filename="file:///home/vedh/workspaces/lawd_ws/install/lawd_description/share/lawd_description/meshes/base_link.stl" scale="0.001 0.001 0.001"/>
      </geometry>
      <material name="white"/>
    </visual>
    <collision>
      <origin rpy="0 0 0" xyz="0 0 0"/>
      <geometry>
        <mesh filename="file:///home/vedh/workspaces/lawd_ws/install/lawd_description/share/lawd_description/meshes/base_link.stl" scale="0.001 0.001 0.001"/>
      </geometry>
    </collision>
  </link>
  <link name="front_left_ext">
    <inertial>
      <origin rpy="0 0 0" xyz="-0.003968707616274422 -0.011528811891692872 -0.05580009747380574"/>
      <mass value="0.061544258405820604"/>
      <inertia ixx="4.7e-05" ixy="3e-06" ixz="-4e-06" iyy="4.7e-05" iyz="-4e-06" izz="1.9e-05"/>
    </inertial>
    <visual>
      <origin rpy="0 0 0" xyz="0.085989 -0.009337 -0.2"/>
      <geometry>
        <mesh filename="file:///home/vedh/workspaces/lawd_ws/install/lawd_description/share/lawd_description/meshes/front_left_ext_1.stl" scale="0.001 0.001 0.001"/>
      </geometry>
      <material name="blue"/>
    </visual>
    <collision>
      <origin rpy="0 0 0" xyz="0.085989 -0.009337 -0.2"/>
      <geometry>
        <mesh filename="file:///home/vedh/workspaces/lawd_ws/install/lawd_description/share/lawd_description/meshes/front_left_ext_1.stl" scale="0.001 0.001 0.001"/>
      </geometry>
    </collision>
  </link>
  <link name="back_left_ext">
    <inertial>
      <origin rpy="0 0 0" xyz="-0.003968748505297609 -0.011529094949763743 -0.05580009747380574"/>
      <mass value="0.061544258405820604"/>
      <inertia ixx="4.7e-05" ixy="3e-06" ixz="-4e-06" iyy="4.7e-05" iyz="-4e-06" izz="1.9e-05"/>
    </inertial>
    <visual>
      <origin rpy="0 0 0" xyz="-0.001768 0.07869 -0.2"/>
      <geometry>
        <mesh filename="file:///home/vedh/workspaces/lawd_ws/install/lawd_description/share/lawd_description/meshes/back_left_ext_1.stl" scale="0.001 0.001 0.001"/>
      </geometry>
      <material name="blue"/>
    </visual>
    <collision>
      <origin rpy="0 0 0" xyz="-0.001768 0.07869 -0.2"/>
      <geometry>
        <mesh filename="file:///home/vedh/workspaces/lawd_ws/install/lawd_description/share/lawd_description/meshes/back_left_ext_1.stl" scale="0.001 0.001 0.001"/>
      </geometry>
    </collision>
  </link>
  <link name="front_right_ext">
    <inertial>
      <origin rpy="0 0 0" xyz="0.012783369116821387 -0.0009200116016966631 -0.05572297183409802"/>
      <mass value="0.06193296037863335"/>
      <inertia ixx="4.7e-05" ixy="3e-06" ixz="4e-06" iyy="4.7e-05" iyz="4e-06" izz="1.9e-05"/>
    </inertial>
    <visual>
      <origin rpy="0 0 0" xyz="0.010606 -0.091144 -0.2"/>
      <geometry>
        <mesh filename="file:///home/vedh/workspaces/lawd_ws/install/lawd_description/share/lawd_description/meshes/front_right_ext_1.stl" scale="0.001 0.001 0.001"/>
      </geometry>
      <material name="blue"/>
    </visual>
    <collision>
      <origin rpy="0 0 0" xyz="0.010606 -0.091144 -0.2"/>
      <geometry>
        <mesh filename="file:///home/vedh/workspaces/lawd_ws/install/lawd_description/share/lawd_description/meshes/front_right_ext_1.stl" scale="0.001 0.001 0.001"/>
      </geometry>
    </collision>
  </link>
  <link name="back_right_ext">
    <inertial>
      <origin rpy="0 0 0" xyz="0.012783380118311621 -0.0009203523746881385 -0.05572297183409802"/>
      <mass value="0.06193296037863335"/>
      <inertia ixx="4.7e-05" ixy="3e-06" ixz="4e-06" iyy="4.7e-05" iyz="4e-06" izz="1.9e-05"/>
    </inertial>
    <visual>
      <origin rpy="0 0 0" xyz="-0.077977 -0.002501 -0.2"/>
      <geometry>
        <mesh filename="file:///home/vedh/workspaces/lawd_ws/install/lawd_description/share/lawd_description/meshes/back_right_ext_1.stl" scale="0.001 0.001 0.001"/>
      </geometry>
      <material name="blue"/>
    </visual>
    <collision>
      <origin rpy="0 0 0" xyz="-0.077977 -0.002501 -0.2"/>
      <geometry>
        <mesh filename="file:///home/vedh/workspaces/lawd_ws/install/lawd_description/share/lawd_description/meshes/back_right_ext_1.stl" scale="0.001 0.001 0.001"/>
      </geometry>
    </collision>
  </link>
  <link name="front_left_first">
    <inertial>
      <origin rpy="0 0 0" xyz="-0.02679136374245379 -0.03549021821816391 0.02774172860835955"/>
      <mass value="0.07092250685852575"/>
      <inertia ixx="6.8e-05" ixy="-1.4e-05" ixz="1e-06" iyy="5.2e-05" iyz="-3e-06" izz="4.7e-05"/>
    </inertial>
    <visual>
      <origin rpy="0 0 0" xyz="0.107196 0.005572 -0.1265"/>
      <geometry>
        <mesh filename="file:///home/vedh/workspaces/lawd_ws/install/lawd_description/share/lawd_description/meshes/front_left_first_1.stl" scale="0.001 0.001 0.001"/>
      </geometry>
      <material name="red"/>
    </visual>
    <collision>
      <origin rpy="0 0 0" xyz="0.107196 0.005572 -0.1265"/>
      <geometry>
        <mesh filename="file:///home/vedh/workspaces/lawd_ws/install/lawd_description/share/lawd_description/meshes/front_left_first_1.stl" scale="0.001 0.001 0.001"/>
      </geometry>
    </collision>
  </link>
  <link name="back_left_first">
    <inertial>
      <origin rpy="0 0 0" xyz="-0.026791404631476858 -0.03548950127623447 0.027741728608360272"/>
      <mass value="0.07092250685852575"/>
      <inertia ixx="6.8e-05" ixy="-1.4e-05" ixz="1e-06" iyy="5.2e-05" iyz="-3e-06" izz="4.7e-05"/>
    </inertial>
    <visual>
      <origin rpy="0 0 0" xyz="0.019439 0.0936 -0.1265"/>
      <geometry>
        <mesh filename="file:///home/vedh/workspaces/lawd_ws/install/lawd_description/share/lawd_description/meshes/back_left_first_1.stl" scale="0.001 0.001 0.001"/>
      </geometry>
      <material name="red"/>
    </visual>
    <collision>
      <origin rpy="0 0 0" xyz="0.019439 0.0936 -0.1265"/>
      <geometry>
        <mesh filename="file:///home/vedh/workspaces/lawd_ws/install/lawd_description/share/lawd_description/meshes/back_left_first_1.stl" scale="0.001 0.001 0.001"/>
      </geometry>
    </collision>
  </link>
  <link name="back_right_first">
    <inertial>
      <origin rpy="0 0 0" xyz="0.03549786601917407 0.026797164380325905 0.027749022264601075"/>
      <mass value="0.07090675877539286"/>
      <inertia ixx="5.2e-05" ixy="-1.3e-05" ixz="3e-06" iyy="6.8e-05" iyz="-1e-06" izz="4.7e-05"/>
    </inertial>
    <visual>
      <origin rpy="0 0 0" xyz="-0.093966 -0.019118 -0.1265"/>
      <geometry>
        <mesh filename="file:///home/vedh/workspaces/lawd_ws/install/lawd_description/share/lawd_description/meshes/back_right_first_1.stl" scale="0.001 0.001 0.001"/>
      </geometry>
      <material name="red"/>
    </visual>
    <collision>
      <origin rpy="0 0 0" xyz="-0.093966 -0.019118 -0.1265"/>
      <geometry>
        <mesh filename="file:///home/vedh/workspaces/lawd_ws/install/lawd_description/share/lawd_description/meshes/back_right_first_1.stl" scale="0.001 0.001 0.001"/>
      </geometry>
    </collision>
  </link>
  <link name="front_right_first">
    <inertial>
      <origin rpy="0 0 0" xyz="0.03549785501768482 0.02679750515331672 0.027749022264600826"/>
      <mass value="0.07090675877539286"/>
      <inertia ixx="5.2e-05" ixy="-1.3e-05" ixz="3e-06" iyy="6.8e-05" iyz="-1e-06" izz="4.7e-05"/>
    </inertial>
    <visual>
      <origin rpy="0 0 0" xyz="-0.005383 -0.107761 -0.1265"/>
      <geometry>
        <mesh filename="file:///home/vedh/workspaces/lawd_ws/install/lawd_description/share/lawd_description/meshes/front_right_first_1.stl" scale="0.001 0.001 0.001"/>
      </geometry>
      <material name="red"/>
    </visual>
    <collision>
      <origin rpy="0 0 0" xyz="-0.005383 -0.107761 -0.1265"/>
      <geometry>
        <mesh filename="file:///home/vedh/workspaces/lawd_ws/install/lawd_description/share/lawd_description/meshes/front_right_first_1.stl" scale="0.001 0.001 0.001"/>
      </geometry>
    </collision>
  </link>
  <link name="front_left_sec">
    <inertial>
      <origin rpy="0 0 0" xyz="-0.016605851464971177 0.016606299212651755 -0.05769076418602698"/>
      <mass value="0.10468978828218295"/>
      <inertia ixx="0.000185" ixy="3.4e-05" ixz="-3e-06" iyy="0.000185" iyz="3e-06" izz="7.5e-05"/>
    </inertial>
    <visual>
      <origin rpy="0 0 0" xyz="0.126562 0.073022 -0.143542"/>
      <geometry>
        <mesh filename="file:///home/vedh/workspaces/lawd_ws/install/lawd_description/share/lawd_description/meshes/front_left_sec_1.stl" scale="0.001 0.001 0.001"/>
      </geometry>
      <material name="brown"/>
    </visual>
    <collision>
      <origin rpy="0 0 0" xyz="0.126562 0.073022 -0.143542"/>
      <geometry>
        <mesh filename="file:///home/vedh/workspaces/lawd_ws/install/lawd_description/share/lawd_description/meshes/front_left_sec_1.stl" scale="0.001 0.001 0.001"/>
      </geometry>
    </collision>
  </link>
  <link name="back_left_sec">
    <inertial>
      <origin rpy="0 0 0" xyz="-0.016605892353994497 0.016606016154579933 -0.057690764186026366"/>
      <mass value="0.10468978828218295"/>
      <inertia ixx="0.000185" ixy="3.4e-05" ixz="-3e-06" iyy="0.000185" iyz="3e-06" izz="7.5e-05"/>
    </inertial>
    <visual>
      <origin rpy="0 0 0" xyz="0.038805 0.161049 -0.143542"/>
      <geometry>
        <mesh filename="file:///home/vedh/workspaces/lawd_ws/install/lawd_description/share/lawd_description/meshes/back_left_sec_1.stl" scale="0.001 0.001 0.001"/>
      </geometry>
      <material name="brown"/>
    </visual>
    <collision>
      <origin rpy="0 0 0" xyz="0.038805 0.161049 -0.143542"/>
      <geometry>
        <mesh filename="file:///home/vedh/workspaces/lawd_ws/install/lawd_description/share/lawd_description/meshes/back_left_sec_1.stl" scale="0.001 0.001 0.001"/>
      </geometry>
    </collision>
  </link>
  <link name="front_right_sec">
    <inertial>
      <origin rpy="0 0 0" xyz="-0.016605826993704824 0.016605898496808158 -0.05769076418603017"/>
      <mass value="0.10468978828218295"/>
      <inertia ixx="0.000185" ixy="3.4e-05" ixz="-3e-06" iyy="0.000185" iyz="3e-06" izz="7.5e-05"/>
    </inertial>
    <visual>
      <origin rpy="0 0 0" xyz="-0.072832 -0.127127 -0.143542"/>
      <geometry>
        <mesh filename="file:///home/vedh/workspaces/lawd_ws/install/lawd_description/share/lawd_description/meshes/front_right_sec_1.stl" scale="0.001 0.001 0.001"/>
      </geometry>
      <material name="brown"/>
    </visual>
    <collision>
      <origin rpy="0 0 0" xyz="-0.072832 -0.127127 -0.143542"/>
      <geometry>
        <mesh filename="file:///home/vedh/workspaces/lawd_ws/install/lawd_description/share/lawd_description/meshes/front_right_sec_1.stl" scale="0.001 0.001 0.001"/>
      </geometry>
    </collision>
  </link>
  <link name="back_right_sec">
    <inertial>
      <origin rpy="0 0 0" xyz="-0.016605815992222273 0.016605557723824146 -0.05769076418602456"/>
      <mass value="0.10468978828218295"/>
      <inertia ixx="0.000185" ixy="3.4e-05" ixz="-3e-06" iyy="0.000185" iyz="3e-06" izz="7.5e-05"/>
    </inertial>
    <visual>
      <origin rpy="0 0 0" xyz="-0.161415 -0.038484 -0.143542"/>
      <geometry>
        <mesh filename="file:///home/vedh/workspaces/lawd_ws/install/lawd_description/share/lawd_description/meshes/back_right_sec_1.stl" scale="0.001 0.001 0.001"/>
      </geometry>
      <material name="brown"/>
    </visual>
    <collision>
      <origin rpy="0 0 0" xyz="-0.161415 -0.038484 -0.143542"/>
      <geometry>
        <mesh filename="file:///home/vedh/workspaces/lawd_ws/install/lawd_description/share/lawd_description/meshes/back_right_sec_1.stl" scale="0.001 0.001 0.001"/>
      </geometry>
    </collision>
  </link>
  <link name="front_left_wing">
    <inertial>
      <origin rpy="0 0 0" xyz="-0.08423046213273366 1.2586288960263511e-05 -0.025014546541867244"/>
      <mass value="0.10900064251063164"/>
      <inertia ixx="4.2e-05" ixy="-0.0" ixz="-0.0" iyy="0.000693" iyz="-0.0" izz="0.00067"/>
    </inertial>
    <visual>
      <origin rpy="0 0 0" xyz="0.1425 -4e-05 -0.2645"/>
      <geometry>
        <mesh filename="file:///home/vedh/workspaces/lawd_ws/install/lawd_description/share/lawd_description/meshes/front_left_wing_1.stl" scale="0.001 0.001 0.001"/>
      </geometry>
      <material name="yellow"/>
    </visual>
    <collision>
      <origin rpy="0 0 0" xyz="0.1425 -4e-05 -0.2645"/>
      <geometry>
        <mesh filename="file:///home/vedh/workspaces/lawd_ws/install/lawd_description/share/lawd_description/meshes/front_left_wing_1.stl" scale="0.001 0.001 0.001"/>
      </geometry>
    </collision>
  </link>
  <link name="front_right_wing">
    <inertial>
      <origin rpy="0 0 0" xyz="1.2776731160215605e-05 0.08423040102887916 -0.025014546541867272"/>
      <mass value="0.10900064251063164"/>
      <inertia ixx="0.000693" ixy="0.0" ixz="-0.0" iyy="4.2e-05" iyz="0.0" izz="0.00067"/>
    </inertial>
    <visual>
      <origin rpy="0 0 0" xyz="-0.0 -0.142742 -0.265"/>
      <geometry>
        <mesh filename="file:///home/vedh/workspaces/lawd_ws/install/lawd_description/share/lawd_description/meshes/front_right_wing_1.stl" scale="0.001 0.001 0.001"/>
      </geometry>
      <material name="yellow"/>
    </visual>
    <collision>
      <origin rpy="0 0 0" xyz="-0.0 -0.142742 -0.265"/>
      <geometry>
        <mesh filename="file:///home/vedh/workspaces/lawd_ws/install/lawd_description/share/lawd_description/meshes/front_right_wing_1.stl" scale="0.001 0.001 0.001"/>
      </geometry>
    </collision>
  </link>
  <link name="back_left_wing">
    <inertial>
      <origin rpy="0 0 0" xyz="-1.2776424201028646e-05 -0.08423040102887927 -0.025014544480448514"/>
      <mass value="0.10900064251063164"/>
      <inertia ixx="0.000693" ixy="0.0" ixz="0.0" iyy="4.2e-05" iyz="-0.0" izz="0.00067"/>
    </inertial>
    <visual>
      <origin rpy="0 0 0" xyz="-0.0 0.142742 -0.265"/>
      <geometry>
        <mesh filename="file:///home/vedh/workspaces/lawd_ws/install/lawd_description/share/lawd_description/meshes/back_left_wing_1.stl" scale="0.001 0.001 0.001"/>
      </geometry>
      <material name="green"/>
    </visual>
    <collision>
      <origin rpy="0 0 0" xyz="-0.0 0.142742 -0.265"/>
      <geometry>
        <mesh filename="file:///home/vedh/workspaces/lawd_ws/install/lawd_description/share/lawd_description/meshes/back_left_wing_1.stl" scale="0.001 0.001 0.001"/>
      </geometry>
    </collision>
  </link>
  <link name="back_right_wing">
    <inertial>
      <origin rpy="0 0 0" xyz="0.08423046213273397 -1.2966709102273344e-05 -0.02501417790470281"/>
      <mass value="0.10900064251063164"/>
      <inertia ixx="4.2e-05" ixy="-0.0" ixz="0.0" iyy="0.000693" iyz="0.0" izz="0.00067"/>
    </inertial>
    <visual>
      <origin rpy="0 0 0" xyz="-0.1425 -4e-05 -0.264887"/>
      <geometry>
        <mesh filename="file:///home/vedh/workspaces/lawd_ws/install/lawd_description/share/lawd_description/meshes/back_right_wing_1.stl" scale="0.001 0.001 0.001"/>
      </geometry>
      <material name="green"/>
    </visual>
    <collision>
      <origin rpy="0 0 0" xyz="-0.1425 -4e-05 -0.264887"/>
      <geometry>
        <mesh filename="file:///home/vedh/workspaces/lawd_ws/install/lawd_description/share/lawd_description/meshes/back_right_wing_1.stl" scale="0.001 0.001 0.001"/>
      </geometry>
    </collision>
  </link>
  <link name="back_left_prop">
    <inertial>
      <origin rpy="0 0 0" xyz="-5.5371578022784715e-09 6.110385503133031e-08 0.005000002061418818"/>
      <mass value="0.009084450684452723"/>
      <inertia ixx="3.3e-09" ixy="-0.0" ixz="0.0" iyy="3.3e-05" iyz="0.0" izz="3.3e-05"/>
    </inertial>
    <visual>
      <origin rpy="0 0 0" xyz="1e-05 0.374024 -0.255"/>
      <geometry>
        <mesh filename="file:///home/vedh/workspaces/lawd_ws/install/lawd_description/share/lawd_description/meshes/back_left_prop_1.stl" scale="0.001 0.001 0.001"/>
      </geometry>
      <material name="black"/>
    </visual>
    <collision>
      <origin rpy="0 0 0" xyz="1e-05 0.374024 -0.255"/>
      <geometry>
        <mesh filename="file:///home/vedh/workspaces/lawd_ws/install/lawd_description/share/lawd_description/meshes/back_left_prop_1.stl" scale="0.001 0.001 0.001"/>
      </geometry>
    </collision>
  </link>
  <link name="back_right_prop">
    <inertial>
      <origin rpy="0 0 0" xyz="6.48925357893404e-14 -1.9582212303134847e-07 0.005000368637164465"/>
      <mass value="0.007573563096933218"/>
      <inertia ixx="3.3e-09" ixy="-0.0" ixz="0.0" iyy="2.8e-05" iyz="0.0" izz="2.8e-05"/>
    </inertial>
    <visual>
      <origin rpy="0 0 0" xyz="-0.373782 -3e-05 -0.254887"/>
      <geometry>
        <mesh filename="file:///home/vedh/workspaces/lawd_ws/install/lawd_description/share/lawd_description/meshes/back_right_prop_1.stl" scale="0.001 0.001 0.001"/>
      </geometry>
      <material name="violet"/>
    </visual>
    <collision>
      <origin rpy="0 0 0" xyz="-0.373782 -3e-05 -0.254887"/>
      <geometry>
        <mesh filename="file:///home/vedh/workspaces/lawd_ws/install/lawd_description/share/lawd_description/meshes/back_right_prop_1.stl" scale="0.001 0.001 0.001"/>
      </geometry>
    </collision>
  </link>
  <link name="front_right_prop">
    <inertial>
      <origin rpy="0 0 0" xyz="5.844245561943996e-09 -6.110385486479686e-08 0.0050000000000000044"/>
      <mass value="0.009084450684452723"/>
      <inertia ixx="3.3e-09" ixy="-0.0" ixz="0.0" iyy="3.3e-05" iyz="0.0" izz="3.3e-05"/>
    </inertial>
    <visual>
      <origin rpy="0 0 0" xyz="-1e-05 -0.374024 -0.255"/>
      <geometry>
        <mesh filename="file:///home/vedh/workspaces/lawd_ws/install/lawd_description/share/lawd_description/meshes/front_right_prop_1.stl" scale="0.001 0.001 0.001"/>
      </geometry>
      <material name="black"/>
    </visual>
    <collision>
      <origin rpy="0 0 0" xyz="-1e-05 -0.374024 -0.255"/>
      <geometry>
        <mesh filename="file:///home/vedh/workspaces/lawd_ws/install/lawd_description/share/lawd_description/meshes/front_right_prop_1.stl" scale="0.001 0.001 0.001"/>
      </geometry>
    </collision>
  </link>
  <link name="front_left_prop">
    <inertial>
      <origin rpy="0 0 0" xyz="6.461498003318411e-14 -1.845980186942605e-07 0.00500000000000006"/>
      <mass value="0.007573563096933218"/>
      <inertia ixx="3.3e-09" ixy="-0.0" ixz="0.0" iyy="2.8e-05" iyz="0.0" izz="2.8e-05"/>
    </inertial>
    <visual>
      <origin rpy="0 0 0" xyz="0.373782 -5e-05 -0.2545"/>
      <geometry>
        <mesh filename="file:///home/vedh/workspaces/lawd_ws/install/lawd_description/share/lawd_description/meshes/front_left_prop_1.stl" scale="0.001 0.001 0.001"/>
      </geometry>
      <material name="violet"/>
    </visual>
    <collision>
      <origin rpy="0 0 0" xyz="0.373782 -5e-05 -0.2545"/>
      <geometry>
        <mesh filename="file:///home/vedh/workspaces/lawd_ws/install/lawd_description/share/lawd_description/meshes/front_left_prop_1.stl" scale="0.001 0.001 0.001"/>
      </geometry>
    </collision>
  </link>
  <joint name="base_frontleftext" type="fixed">
    <origin rpy="0 0 0" xyz="-0.085989 0.009337 0.2"/>
    <parent link="base_link"/>
    <child link="front_left_ext"/>
  </joint>
  <joint name="base_backleftext" type="fixed">
    <origin rpy="0 0 0" xyz="0.001768 -0.07869 0.2"/>
    <parent link="base_link"/>
    <child link="back_left_ext"/>
  </joint>
  <joint name="base_frontrightext" type="fixed">
    <origin rpy="0 0 0" xyz="-0.010606 0.091144 0.2"/>
    <parent link="base_link"/>
    <child link="front_right_ext"/>
  </joint>
  <joint name="base_backrightext" type="fixed">
    <origin rpy="0 0 0" xyz="0.077977 0.002501 0.2"/>
    <parent link="base_link"/>
    <child link="back_right_ext"/>
  </joint>
  <joint name="ext_frontleftfirst" type="revolute">
    <origin rpy="0 0 0" xyz="-0.021207 -0.014909 -0.0735"/>
    <parent link="front_left_ext"/>
    <child link="front_left_first"/>
    <axis xyz="0.0 -0.0 1.0"/>
    <limit effort="100" lower="-1.570796" upper="1.570796" velocity="100"/>
  </joint>
  <joint name="ext_backleftfirst" type="revolute">
    <origin rpy="0 0 0" xyz="-0.021207 -0.01491 -0.0735"/>
    <parent link="back_left_ext"/>
    <child link="back_left_first"/>
    <axis xyz="0.0 -0.0 1.0"/>
    <limit effort="100" lower="-1.570796" upper="1.570796" velocity="100"/>
  </joint>
  <joint name="ext_backrightfirst" type="revolute">
    <origin rpy="0 0 0" xyz="0.015989 0.016617 -0.0735"/>
    <parent link="back_right_ext"/>
    <child link="back_right_first"/>
    <axis xyz="0.0 -0.0 1.0"/>
    <limit effort="100" lower="-1.570796" upper="1.570796" velocity="100"/>
  </joint>
  <joint name="ext_frontrightfirst" type="revolute">
    <origin rpy="0 0 0" xyz="0.015989 0.016617 -0.0735"/>
    <parent link="front_right_ext"/>
    <child link="front_right_first"/>
    <axis xyz="0.0 -0.0 1.0"/>
    <limit effort="100" lower="-1.570796" upper="1.570796" velocity="100"/>
  </joint>
  <joint name="first_frontleftsec" type="revolute">
    <origin rpy="0 0 0" xyz="-0.019366 -0.06745 0.017042"/>
    <parent link="front_left_first"/>
    <child link="front_left_sec"/>
    <axis xyz="0.707107 -0.707107 0.0"/>
    <limit effort="100" lower="-0.523599" upper="1.745329" velocity="100"/>
  </joint>
  <joint name="first_backleftsec" type="revolute">
    <origin rpy="0 0 0" xyz="-0.019366 -0.067449 0.017042"/>
    <parent link="back_left_first"/>
    <child link="back_left_sec"/>
    <axis xyz="0.707107 -0.707107 0.0"/>
    <limit effort="100" lower="-0.523599" upper="1.745329" velocity="100"/>
  </joint>
  <joint name="first_frontrightsec" type="revolute">
    <origin rpy="0 0 0" xyz="0.067449 0.019366 0.017042"/>
    <parent link="front_right_first"/>
    <child link="front_right_sec"/>
    <axis xyz="0.707107 -0.707107 -0.0"/>
    <limit effort="100" lower="-1.745329" upper="0.523599" velocity="100"/>
  </joint>
  <joint name="first_backrightsec" type="revolute">
    <origin rpy="0 0 0" xyz="0.067449 0.019366 0.017042"/>
    <parent link="back_right_first"/>
    <child link="back_right_sec"/>
    <axis xyz="0.707107 -0.707107 0.0"/>
    <limit effort="100" lower="-1.745329" upper="0.523599" velocity="100"/>
  </joint>
  <joint name="base_frontleftwing" type="revolute">
    <origin rpy="0 0 0" xyz="-0.1425 4e-05 0.2645"/>
    <parent link="base_link"/>
    <child link="front_left_wing"/>
    <axis xyz="0.0 -0.0 1.0"/>
    <limit effort="100" lower="-1.570796" upper="1.570796" velocity="100"/>
  </joint>
  <joint name="base_frontrightwing" type="revolute">
    <origin rpy="0 0 0" xyz="0.0 0.142742 0.265"/>
    <parent link="base_link"/>
    <child link="front_right_wing"/>
    <axis xyz="0.0 -0.0 1.0"/>
    <limit effort="100" lower="-1.570796" upper="1.570796" velocity="100"/>
  </joint>
  <joint name="base_backleftwing" type="revolute">
    <origin rpy="0 0 0" xyz="0.0 -0.142742 0.265"/>
    <parent link="base_link"/>
    <child link="back_left_wing"/>
    <axis xyz="0.0 -0.0 1.0"/>
    <limit effort="100" lower="-1.570796" upper="1.570796" velocity="100"/>
  </joint>
  <joint name="base_backrightwing" type="revolute">
    <origin rpy="0 0 0" xyz="0.1425 4e-05 0.264887"/>
    <parent link="base_link"/>
    <child link="back_right_wing"/>
    <axis xyz="0.0 -0.0 1.0"/>
    <limit effort="100" lower="-1.570796" upper="1.570796" velocity="100"/>
  </joint>
  <joint name="wing_backleftprop" type="continuous">
    <origin rpy="0 0 0" xyz="-1e-05 -0.231282 -0.01"/>
    <parent link="back_left_wing"/>
    <child link="back_left_prop"/>
    <axis xyz="0.0 -0.0 1.0"/>
  </joint>
  <joint name="wing_backrightprop" type="continuous">
    <origin rpy="0 0 0" xyz="0.231282 -1e-05 -0.01"/>
    <parent link="back_right_wing"/>
    <child link="back_right_prop"/>
    <axis xyz="0.0 -0.0 1.0"/>
  </joint>
  <joint name="wing_frontrightprop" type="continuous">
    <origin rpy="0 0 0" xyz="1e-05 0.231282 -0.01"/>
    <parent link="front_right_wing"/>
    <child link="front_right_prop"/>
    <axis xyz="0.0 -0.0 1.0"/>
  </joint>
  <joint name="wing_frontleftprop" type="continuous">
    <origin rpy="0 0 0" xyz="-0.231282 1e-05 -0.01"/>
    <parent link="front_left_wing"/>
    <child link="front_left_prop"/>
    <axis xyz="0.0 -0.0 1.0"/>
  </joint>
</robot>
